Workbook

Sheet 1st
A1: Zouki Westmead | G1: should be $0
A2: 45870 | B2: Cash Read | C2: CC Read | D2: Cash Collected | E2: Eftpos Collected | F2: +/- over under Cash | G2: +/- over under CC | H2: Acc/smart Cards | I2: GST Read
A3: COFFEE THERAPY | B3: 76.3 | C3: 560.06 | D3: 76.3 | E3: 560.06 | F3: =D3-B3 -> 0 | G3: =E3-C3 -> 0 | I3: 46.33
A4: HEALTHY FILLINGS | E4: =SUM(E32+F32) -> 0 | F4: =D4-B4 -> 0 | G4: =E4-C4 -> 0
A5: OUTPATIENT | B5: 110.9 | C5: 2266.92 | D5: 110.9 | E5: 2266.92 | F5: =D5-B5 -> 0 | G5: =E5-C5 -> 0 | I5: 168.7
A6: COFFEE BOX | B6: 164.1 | C6: 913.74 | D6: 164.1 | E6: 913.74 | F6: =D6-B6 -> 0 | G6: =E6-C6 -> 0 | I6: 83.03
A7: Green Organic | B7: 125 | C7: 776.83 | D7: 125 | E7: 776.83 | F7: =D7-B7 -> 0 | G7: =E7-C7 -> 0 | I7: 62.68
A8: Till 1 Coffee Left | B8: 175.2 | C8: 1715.25 | D8: 165.1 | E8: 1715.25 | F8: =D8-B8 -> -10.1 | G8: =E8-C8 -> 0 | I8: 201.1
A9: Till 2 Coffee Right | B9: 658.2 | C9: 3192.36 | D9: =678.7 -> 678.7 | E9: 3192.36 | F9: =D9-B9+B40 -> 20.5 | G9: =E9-C9 -> 0 | I9: 231.47
A10: Till 3 Sushi | E10: =SUM(E38+F38) -> 0 | F10: =D10-B10 -> 0 | G10: =E10-C10 -> 0
A11: Till 4 Panine | B11: 338.2 | C11: 1712.6 | D11: 334.25 | E11: 1712.6 | F11: =D11-B11 -> -3.95 | G11: =E11-C11 -> 0 | I11: 139.25
A12: Till 5 Salad | E12: =SUM(E40+F40) -> 0 | F12: =D12-B12 -> 0 | G12: =E12-C12 -> 0
A13: Till 6 Pizza | B13: 139.7 | C13: 734.44 | D13: 141.4 | E13: 734.44 | F13: =D13-B13 -> 1.7 | G13: =E13-C13 -> 0 | I13: 71.03
A14: Till 7 Kebab | B14: 267.9 | C14: 1185.02 | D14: 277 | E14: 1185.02 | F14: =D14-B14 -> 9.1 | G14: =E14-C14 -> 0 | I14: 125.85
A15: Till 8 Hot Food | B15: 67.8 | C15: 829.07 | D15: 67.8 | E15: 829.07 | F15: =D15-B15 -> 0 | G15: =E15-C15 -> 0 | I15: 73.27
A16: Till 9 Wok | B16: 1106.5 | C16: 5400.95 | D16: 1106.5 | E16: 5400.95 | F16: =D16-B16 -> 0 | G16: =E16-C16 -> 0 | I16: 498.37
A17: Till 10 Juice Bar | B17: 212.9 | C17: 484.24 | D17: 213.9 | E17: 484.24 | F17: =D17-B17 -> 1 | G17: =E17-C17 -> 0 | I17: 1.73
A18: Main Cafe Total | B18: =SUM(B8:B17) -> 2966.4 | C18: =SUM(C8:C17) -> 15253.93 | D18: =SUM(D8:D17) -> 2984.65 | E18: =SUM(E8:E17) -> 15253.93 | F18: =SUM(F8:F17) -> 18.25 | G18: =SUM(G8:G17) -> 0 | H18: =SUM(H8:H17) -> 0 | I18: =SUM(I8:I17) -> 1342.07
A19: Catering on the same day | B19: =SUM(D104) -> 0 | C19: =F104+E104 -> 0 | E19: =SUM(E46+F46-E47-F47) -> 0 | F19: =D19-B19 -> 0 | G19: =E19-C19 -> 0 | H19: =SUM(C118) -> 0 | I19: =(D19+E19+H19)*0.95/11 -> 0
A20: Smart App café
A21: Smart App catering
A22: Westend
A23: TOTAL | B23: =SUM(B3+B4+B5+B6+B7+B18+B19+B22) -> 3442.7 | C23: =SUM(C3+C4+C5+C6+C7+C18+C19+C20+C21+C22) -> 19771.48 | D23: =SUM(D3+D4+D5+D6+D7+D18+D19+D20+D21+D22)-C40 -> -0.01 | E23: =SUM(E3+E4+E5+E6+E7+E18+E19+E20+E21+E22) -> 19771.48 | F23: =SUM(F3+F4+F5+F6+F7+F18+F19+F20+F21+F22) -> 18.25 | G23: =SUM(G3+G4+G5+G6+G7+G18+G19+G20+G21+G22) -> 0 | H23: =SUM(H3+H4+H5+H6+H7+H18+H19+H20+H21+H22) -> 0 | I23: =SUM(I3+I4+I5+I6+I7+I18+I19+I20+I21+I22) -> 1702.81
A24: Cash
A25: INVOICES PAID Cash | B25: Total Inc GST | C25: use till coffee right only | E25: Banking Details | G25: Amount deposited
A26: patrick inv 244536 | C26: 1850.06 | E26: Name of Staff | G26: Bank branch
A27: patrickinv 244848 | C27: 1539.1 | E27: Reciept | G27: Time | H27: :
A28: parking | C28: =24.2+12 -> 36.2 | H28: Last Month Safe Total
A29: jerome zouki | C29: 35.6 | H29: Today Total income | I29: =SUM(B23+C23+G23+F23+H23-I23) -> 21529.62
A30: SUPPLIER5 | D30: Credit Cards Reconcile | E30: Amex | F30: CR+DR | H30: TOTAL $ in SAFE | I30: =SUM(I28+D23-H25+D90) -> -0.01
A31: SUPPLIER6 | D31: COFFEE THERAPY
A32: SUPPLIER7 | D32: HEALTHY FILLINGS
A33: SUPPLIER8 | D33: OUTPATIENT
A34: SUPPLIER9 | D34: COFFEE BOX
A35: SUPPLIER10 | D35: Green Organic
A36: SUPPLIER11 | D36: Till 1 Coffee Left
A37: SUPPLIER12 | D37: Till 2 Coffee Right
A38: SUPPLIER13 | D38: Till 3 Sushi
A39: SUPPLIER14 | D39: Till 4 Panine
A40: TOTAL Bills Paid Cash | B40: =SUM(B26:B39) -> 0 | C40: =SUM(C26:C39) -> 3460.96 | D40: Till 5 Salad
...

Sheet 2nd
A1: Zouki Westmead | G1: should be $0
A2: =SUM('1st'!A2 +1) -> 45871 | B2: Cash Read | C2: CC Read | D2: Cash Collected | E2: Eftpos Collected | F2: +/- over under Cash | G2: +/- over under CC | H2: Acc/smart Cards | I2: GST Read
A3: COFFEE THERAPY | E3: =SUM(E31+F31) -> 0 | F3: =D3-B3 -> 0 | G3: =E3-C3 -> 0
A4: HEALTHY FILLINGS | E4: =SUM(E32+F32) -> 0 | F4: =D4-B4 -> 0 | G4: =E4-C4 -> 0
A5: OUTPATIENT | E5: =SUM(E33+F33) -> 0 | F5: =D5-B5 -> 0 | G5: =E5-C5 -> 0
A6: COFFEE BOX | E6: =SUM(E34+F34) -> 0 | F6: =D6-B6 -> 0 | G6: =E6-C6 -> 0
A7: Green Organic | E7: =SUM(E35+F35) -> 0 | F7: =D7-B7 -> 0 | G7: =E7-C7 -> 0
A8: Till 1 Coffee Left | B8: 491.6 | C8: 3855.99 | D8: 491.6 | E8: 3855.99 | F8: =D8-B8 -> 0 | G8: =E8-C8 -> 0 | I8: 252.34
A9: Till 2 Coffee Right | E9: =SUM(E37+F37) -> 0 | G9: =E9-C9 -> 0
A10: Till 3 Sushi | E10: =SUM(E38+F38) -> 0 | F10: =D10-B10 -> 0 | G10: =E10-C10 -> 0
A11: Till 4 Panine | E11: =SUM(E39+F39) -> 0 | F11: =D11-B11 -> 0 | G11: =E11-C11 -> 0
A12: Till 5 Salad | E12: =SUM(E40+F40) -> 0 | F12: =D12-B12 -> 0 | G12: =E12-C12 -> 0
A13: Till 6 Pizza | E13: =SUM(E41+F41) -> 0 | F13: =D13-B13 -> 0 | G13: =E13-C13 -> 0
A14: Till 7 Kebab | B14: 85.6 | C14: 646.85 | D14: 85.6 | E14: 646.85 | F14: =D14-B14 -> 0 | G14: =E14-C14 -> 0 | I14: 64.75
A15: Till 8 Hot Food | E15: =SUM(E43+F43) -> 0 | F15: =D15-B15 -> 0 | G15: =E15-C15 -> 0
A16: Till 9 Wok | B16: 476.3 | C16: 3066.91 | D16: 476.3 | E16: 3066.91 | F16: =D16-B16 -> 0 | G16: =E16-C16 -> 0 | I16: 242.81
A17: Till 10 Juice Bar | E17: =SUM(E45+F45) -> 0 | F17: =D17-B17 -> 0 | G17: =E17-C17 -> 0
A18: Main Cafe Total | B18: =SUM(B8:B17) -> 1053.5 | C18: =SUM(C8:C17) -> 7569.75 | D18: =SUM(D8:D17) -> 1053.5 | E18: =SUM(E8:E17) -> 7569.75 | F18: =SUM(F8:F17) -> 0 | G18: =SUM(G8:G17) -> 0 | H18: =SUM(H8:H17) -> 0 | I18: =SUM(I8:I17) -> 559.9
A19: Catering on the same day | B19: =SUM(D104) -> 0 | C19: =F104+E104 -> 0 | E19: =SUM(E46+F46-E47-F47) -> 0 | F19: =D19-B19 -> 0 | G19: =E19-C19 -> 0 | H19: =SUM(C118) -> 0 | I19: =(D19+E19+H19)*0.95/11 -> 0
A20: Smart App café
A21: Smart App catering
A22: Westend
A23: TOTAL | B23: =SUM(B3+B4+B5+B6+B7+B18+B19+B22) -> 1053.5 | C23: =SUM(C3+C4+C5+C6+C7+C18+C19+C20+C21+C22) -> 7569.75 | D23: =SUM(D3+D4+D5+D6+D7+D18+D19+D20+D21+D22)-C40 -> 0 | E23: =SUM(E3+E4+E5+E6+E7+E18+E19+E20+E21+E22) -> 7569.75 | F23: =SUM(F3+F4+F5+F6+F7+F18+F19+F20+F21+F22) -> 0 | G23: =SUM(G3+G4+G5+G6+G7+G18+G19+G20+G21+G22) -> 0 | H23: =SUM(H3+H4+H5+H6+H7+H18+H19+H20+H21+H22) -> 0 | I23: =SUM(I3+I4+I5+I6+I7+I18+I19+I20+I21+I22) -> 559.9
A24: Cash
A25: INVOICES PAID Cash | B25: Total Inc GST | C25: use till coffee right only | E25: Banking details | G25: Amount deposited
A26: patricikb 245127 | C26: 1053.5 | E26: Name of Staff | G26: Bank branch
A27: SUPPLIER2 | E27: Reciept | G27: Time | H27: :
A28: SUPPLIER3
A29: SUPPLIER4 | H29: Today Total income | I29: =SUM(B23+C23+G23+F23+H23-I23) -> 8063.35
A30: SUPPLIER5 | D30: Credit Cards Reconcile | E30: Amex | F30: CR+DR | H30: TOTAL $ in SAFE | I30: =SUM(D23+'1st'!I30-'2nd'!H25) -> -0.01
A31: SUPPLIER6 | D31: COFFEE THERAPY
A32: SUPPLIER7 | D32: HEALTHY FILLINGS | F32: =SUM(F60+G60) -> 0
A33: SUPPLIER8 | D33: OUTPATIENT
A34: SUPPLIER9 | D34: COFFEE BOX
A35: SUPPLIER10 | D35: Green Organic
A36: SUPPLIER11 | D36: Till 1 Coffee Left
A37: SUPPLIER12 | D37: Till 2 Coffee Right | F37: =SUM(F65+G65) -> 0
A38: SUPPLIER13 | D38: Till 3 Sushi | F38: =SUM(F66+G66) -> 0
A39: SUPPLIER14 | D39: Till 4 Panine
A40: TOTAL Bills Paid Cash | B40: =SUM(B26:B39) -> 0 | C40: =SUM(C26:C39) -> 1053.5 | D40: Till 5 Salad | F40: =SUM(F68+G68) -> 0
...

Sheet 3rd
A1: Zouki Westmead | G1: should be $0
A2: =SUM('2nd'!A2+1) -> 45872 | B2: Cash Read | C2: CC Read | D2: Cash Collected | E2: Eftpos Collected | F2: +/- over under Cash | G2: +/- over under CC | H2: Acc/smart Cards | I2: GST Read
A3: COFFEE THERAPY | F3: =D3-B3 -> 0 | G3: =E3-C3 -> 0
A4: HEALTHY FILLINGS | E4: =SUM(E32+F32) -> 0 | F4: =D4-B4 -> 0 | G4: =E4-C4 -> 0
A5: OUTPATIENT | E5: =SUM(E33+F33) -> 0 | F5: =D5-B5 -> 0 | G5: =E5-C5 -> 0
A6: COFFEE BOX | E6: =SUM(E34+F34) -> 0 | F6: =D6-B6 -> 0 | G6: =E6-C6 -> 0
A7: Green Organic | E7: =SUM(E35+F35) -> 0 | F7: =D7-B7 -> 0 | G7: =E7-C7 -> 0
A8: Till 1 Coffee Left | B8: 510.1 | C8: 3018.2 | D8: 510.1 | E8: 3018.2 | F8: =D8-B8 -> 0 | G8: =E8-C8 -> 0 | I8: 194.39
A9: Till 2 Coffee Right | E9: =SUM(E37+F37) -> 0 | F9: =D9-B9+B40 -> 0 | G9: =E9-C9 -> 0
A10: Till 3 Sushi | E10: =SUM(E38+F38) -> 0 | F10: =D10-B10 -> 0 | G10: =E10-C10 -> 0
A11: Till 4 Panine | E11: =SUM(E39+F39) -> 0 | F11: =D11-B11 -> 0 | G11: =E11-C11 -> 0
A12: Till 5 Salad | E12: =SUM(E40+F40) -> 0 | F12: =D12-B12 -> 0 | G12: =E12-C12 -> 0
A13: Till 6 Pizza | E13: =SUM(E41+F41) -> 0 | F13: =D13-B13 -> 0 | G13: =E13-C13 -> 0
A14: Till 7 Kebab | B14: 98.8 | C14: 455.84 | D14: 98.8 | E14: 455.84 | F14: =D14-B14 -> 0 | G14: =E14-C14 -> 0 | I14: 48.94
A15: Till 8 Hot Food | E15: =SUM(E43+F43) -> 0 | F15: =D15-B15 -> 0 | G15: =E15-C15 -> 0
A16: Till 9 Wok | B16: 484.1 | C16: 2499.49 | D16: 484.1 | E16: 2499.149 | F16: =D16-B16 -> 0 | G16: =E16-C16 -> -0.341 | I16: 189.65
A17: Till 10 Juice Bar | E17: =SUM(E45+F45) -> 0 | F17: =D17-B17 -> 0 | G17: =E17-C17 -> 0
A18: Main Cafe Total | B18: =SUM(B8:B17) -> 1093 | C18: =SUM(C8:C17) -> 5973.53 | D18: =SUM(D8:D17) -> 1093 | E18: =SUM(E8:E17) -> 5973.189 | F18: =SUM(F8:F17) -> 0 | G18: =SUM(G8:G17) -> -0.341 | H18: =SUM(H8:H17) -> 0 | I18: =SUM(I8:I17) -> 432.98
A19: Catering on the same day | B19: =SUM(D104) -> 0 | C19: =F104+E104 -> 0 | E19: =SUM(E46+F46-E47-F47) -> 0 | F19: =D19-B19 -> 0 | G19: =E19-C19 -> 0 | H19: =SUM(C118) -> 0 | I19: =(D19+E19+H19)*0.95/11 -> 0
A20: Smart App café
A21: Smart App catering
A22: Westend
A23: TOTAL | B23: =SUM(B3+B4+B5+B6+B7+B18+B19+B22) -> 1093 | C23: =SUM(C3+C4+C5+C6+C7+C18+C19+C20+C21+C22) -> 5973.53 | D23: =SUM(D3+D4+D5+D6+D7+D18+D19+D20+D21+D22)-274.3-535-165-28-90.7 -> 0 | E23: =SUM(E3+E4+E5+E6+E7+E18+E19+E20+E21+E22) -> 5973.189 | F23: =SUM(F3+F4+F5+F6+F7+F18+F19+F20+F21+F22) -> 0 | G23: =SUM(G3+G4+G5+G6+G7+G18+G19+G20+G21+G22) -> -0.341 | H23: =SUM(H3+H4+H5+H6+H7+H18+H19+H20+H21+H22) -> 0 | I23: =SUM(I3+I4+I5+I6+I7+I18+I19+I20+I21+I22) -> 432.98
A24: Cash
A25: INVOICES PAID Cash | B25: Total Inc GST | C25: use till coffee right only | E25: Banking details | G25: Amount deposited
A26: patricks inv 245127 | C26: 274.3 | E26: Name of Staff | G26: Bank branch
A27: patrikinv 244760 | C27: 534 | E27: Reciept | G27: Time | H27: :
A28: little inida | C28: 164.3
A29: bunnings | C29: 27.9 | H29: Today Total income | I29: =SUM(B23+C23+G23+F23+H23-I23) -> 6633.209
A30: jerome zouki | C30: 90.7 | D30: Credit Cards Reconcile | E30: Amex | F30: CR+DR | H30: TOTAL $ in SAFE | I30: =SUM(D23+'2nd'!I30-'3rd'!H25) -> -0.01
A31: SUPPLIER6 | D31: COFFEE THERAPY
A32: SUPPLIER7 | D32: HEALTHY FILLINGS
A33: SUPPLIER8 | D33: OUTPATIENT
A34: SUPPLIER9 | D34: COFFEE BOX
A35: SUPPLIER10 | D35: Green Organic
A36: SUPPLIER11 | D36: Till 1 Coffee Left
A37: SUPPLIER12 | D37: Till 2 Coffee Right
A38: SUPPLIER13 | D38: Till 3 Sushi
A39: SUPPLIER14 | D39: Till 4 Panine
A40: TOTAL Bills Paid Cash | B40: =SUM(B26:B39) -> 0 | D40: Till 5 Salad
...

Sheet 4th
A1: Zouki Westmead | G1: should be $0
A2: =SUM('3rd'!A2+1) -> 45873 | B2: Cash Read | C2: CC Read | D2: Cash Collected | E2: Eftpos Collected | F2: +/- over under Cash | G2: +/- over under CC | H2: Acc/smart Cards | I2: GST Read
A3: COFFEE THERAPY | B3: 86.6 | C3: 541.39 | D3: 86.6 | E3: 541.39 | F3: =D3-B3 -> 0 | G3: =E3-C3 -> 0 | I3: 44.25
A4: HEALTHY FILLINGS | E4: =SUM(E32+F32) -> 0 | F4: =D4-B4 -> 0 | G4: =E4-C4 -> 0
A5: OUTPATIENT | B5: 242.5 | C5: 2504.69 | D5: 242.5 | E5: 2504.69 | F5: =D5-B5 -> 0 | G5: =E5-C5 -> 0 | I5: 197.18
A6: COFFEE BOX | B6: 169.5 | C6: 922.14 | D6: 169.5 | E6: 922.14 | F6: =D6-B6 -> 0 | G6: =E6-C6 -> 0 | I6: 82.42
A7: Green Organic | B7: 141.9 | C7: 923.6 | D7: 141.9 | E7: 923.6 | F7: =D7-B7 -> 0 | G7: =E7-C7 -> 0 | I7: 73.28
A8: Till 1 Coffee Left | B8: 752.5 | C8: 3913.83 | D8: 752.5 | E8: 3913.83 | F8: =D8-B8 -> 0 | G8: =E8-C8 -> 0 | I8: 273.75
A9: Till 2 Coffee Right | B9: 356.4 | C9: 1760.01 | D9: =150+50+100+55+1.4 -> 356.4 | E9: 1760.01 | F9: =D9-B9+B40 -> 0 | G9: =E9-C9 -> 0 | I9: 131.23
A10: Till 3 Sushi | E10: =SUM(E38+F38) -> 0 | F10: =D10-B10 -> 0 | G10: =E10-C10 -> 0
A11: Till 4 Panine | B11: 309.6 | C11: 1917.04 | D11: 309.6 | E11: 1917.04 | F11: =D11-B11 -> 0 | G11: =E11-C11 -> 0 | I11: 149.88
A12: Till 5 Salad | E12: =SUM(E40+F40) -> 0 | F12: =D12-B12 -> 0 | G12: =E12-C12 -> 0
A13: Till 6 Pizza | B13: 100.1 | C13: 493.43 | D13: 100.1 | E13: 493.43 | F13: =D13-B13 -> 0 | G13: =E13-C13 -> 0 | I13: 47.99
A14: Till 7 Kebab | B14: 270.4 | C14: 1224.29 | D14: 270.4 | E14: 1224.29 | F14: =D14-B14 -> 0 | G14: =E14-C14 -> 0 | I14: 132.08
A15: Till 8 Hot Food | B15: 200.2 | C15: 984.6 | D15: 200.2 | E15: 984.6 | F15: =D15-B15 -> 0 | G15: =E15-C15 -> 0 | I15: 97
A16: Till 9 Wok | B16: 971.1 | C16: 5069.36 | D16: 970.1 | E16: 5069.36 | F16: =D16-B16 -> -1 | G16: =E16-C16 -> 0 | I16: 494.83
A17: Till 10 Juice Bar | B17: 219.1 | C17: 764.13 | D17: 219.1 | E17: 764.13 | F17: =D17-B17 -> 0 | G17: =E17-C17 -> 0 | I17: 0.85
A18: Main Cafe Total | B18: =SUM(B8:B17) -> 3179.4 | C18: =SUM(C8:C17) -> 16126.69 | D18: =SUM(D8:D17) -> 3178.4 | E18: =SUM(E8:E17) -> 16126.69 | F18: =SUM(F8:F17) -> -1 | G18: =SUM(G8:G17) -> 0 | H18: =SUM(H8:H17) -> 0 | I18: =SUM(I8:I17) -> 1327.61
A19: Catering on the same day | B19: =SUM(D104) -> 0 | C19: =F104+E104 -> 0 | E19: =SUM(E46+F46-E47-F47) -> 0 | F19: =D19-B19 -> 0 | G19: =E19-C19 -> 0 | H19: =SUM(C118) -> 0 | I19: =(D19+E19+H19)*0.95/11 -> 0
A20: Smart App café
A21: Smart App catering
A22: Westend
A23: TOTAL | B23: =SUM(B3+B4+B5+B6+B7+B18+B19+B22) -> 3819.9 | C23: =SUM(C3+C4+C5+C6+C7+C18+C19+C20+C21+C22) -> 21018.51 | D23: =SUM(D3+D4+D5+D6+D7+D18+D19+D20+D21+D22)-3818.9 -> 0 | E23: =SUM(E3+E4+E5+E6+E7+E18+E19+E20+E21+E22) -> 21018.51 | F23: =SUM(F3+F4+F5+F6+F7+F18+F19+F20+F21+F22) -> -1 | G23: =SUM(G3+G4+G5+G6+G7+G18+G19+G20+G21+G22) -> 0 | H23: =SUM(H3+H4+H5+H6+H7+H18+H19+H20+H21+H22) -> 0 | I23: =SUM(I3+I4+I5+I6+I7+I18+I19+I20+I21+I22) -> 1724.74
A24: Cash
A25: INVOICES PAID Cash | B25: Total Inc GST | C25: use till coffee right only | E25: Banking details | G25: Amount deposited
A26: elite 0034057 | C26: 3818.9 | E26: Name of Staff | G26: Bank branch
A27: SUPPLIER2 | E27: Reciept | G27: Time | H27: :
A28: SUPPLIER3
A29: SUPPLIER4 | H29: Today Total income | I29: =SUM(B23+C23+G23+F23+H23-I23) -> 23112.67
A30: SUPPLIER5 | D30: Credit Cards Reconcile | E30: Amex | F30: CR+DR | H30: TOTAL $ in SAFE | I30: =SUM(D23+'3rd'!I30-'4th'!H25) -> -0.01
A31: SUPPLIER6 | D31: COFFEE THERAPY
A32: SUPPLIER7 | D32: HEALTHY FILLINGS
A33: SUPPLIER8 | D33: OUTPATIENT
A34: SUPPLIER9 | D34: COFFEE BOX
A35: SUPPLIER10 | D35: Green Organic
A36: SUPPLIER11 | D36: Till 1 Coffee Left
A37: SUPPLIER12 | D37: Till 2 Coffee Right
A38: SUPPLIER13 | D38: Till 3 Sushi
A39: SUPPLIER14 | D39: Till 4 Panine
A40: TOTAL Bills Paid Cash | B40: =SUM(B26:B39) -> 0 | D40: Till 5 Salad
...

Sheet 5th
A1: Zouki Westmead | G1: should be $0
A2: =SUM('4th'!A2+1) -> 45874 | B2: Cash Read | C2: CC Read | D2: Cash Collected | E2: Eftpos Collected | F2: +/- over under Cash | G2: +/- over under CC | H2: Acc/smart Cards | I2: GST Read
A3: COFFEE THERAPY | B3: 91.9 | C3: 480.48 | D3: 91.9 | E3: 480.48 | F3: =D3-B3 -> 0 | G3: =E3-C3 -> 0 | I3: 38.99
A4: HEALTHY FILLINGS | E4: =SUM(E32+F32) -> 0 | F4: =D4-B4 -> 0 | G4: =E4-C4 -> 0
A5: OUTPATIENT | B5: 109.7 | C5: 2376.79 | D5: 109.7 | E5: 2376.79 | F5: =D5-B5 -> 0 | G5: =E5-C5 -> 0 | I5: 175.97
A6: COFFEE BOX | B6: 224.8 | C6: 1113.35 | D6: 224.8 | E6: 1113.35 | F6: =D6-B6 -> 0 | G6: =E6-C6 -> 0 | I6: 101.73
A7: Green Organic | B7: 171.2 | C7: 824.85 | D7: 171.2 | E7: 824.85 | F7: =D7-B7 -> 0 | G7: =E7-C7 -> 0 | I7: 69.88
A8: Till 1 Coffee Left | B8: 693.8 | C8: 2967.35 | D8: =120+350+220+3.8 -> 693.8 | E8: 2967.35 | F8: =D8-B8 -> 0 | G8: =E8-C8 -> 0 | I8: 216.04
A9: Till 2 Coffee Right | B9: 229.9 | C9: 1640.08 | D9: 229.9 | E9: 1640.08 | F9: =D9-B9+B40 -> 0 | G9: =E9-C9 -> 0 | I9: 108.4
A10: Till 3 Sushi | E10: =SUM(E38+F38) -> 0 | F10: =D10-B10 -> 0 | G10: =E10-C10 -> 0
A11: Till 4 Panine | B11: 342.7 | C11: 1509.46 | D11: 342.7 | E11: 1509.46 | F11: =D11-B11 -> 0 | G11: =E11-C11 -> 0 | I11: 133.14
A12: Till 5 Salad | E12: =SUM(E40+F40) -> 0 | F12: =D12-B12 -> 0 | G12: =E12-C12 -> 0
A13: Till 6 Pizza | B13: 125.6 | C13: 524.67 | D13: 125.6 | E13: 524.67 | F13: =D13-B13 -> 0 | G13: =E13-C13 -> 0 | I13: 49.62
A14: Till 7 Kebab | B14: 258.5 | C14: 1156.72 | D14: 243.5 | E14: 1156.72 | F14: =D14-B14 -> -15 | G14: =E14-C14 -> 0 | I14: 122.51
A15: Till 8 Hot Food | B15: 190.9 | C15: 1047.72 | D15: 190.9 | E15: 1047.72 | F15: =D15-B15 -> 0 | G15: =E15-C15 -> 0 | I15: 97.59
A16: Till 9 Wok | B16: 1037.3 | C16: 4791.78 | D16: =800+220+15+2.1 -> 1037.1 | E16: 4791.78 | F16: =D16-B16 -> -0.2 | G16: =E16-C16 -> 0 | I16: 479.86
A17: Till 10 Juice Bar | B17: 268.1 | C17: 735.66 | D17: 268.1 | E17: 735.66 | F17: =D17-B17 -> 0 | G17: =E17-C17 -> 0
A18: Main Cafe Total | B18: =SUM(B8:B17) -> 3146.8 | C18: =SUM(C8:C17) -> 14373.44 | D18: =SUM(D8:D17) -> 3131.6 | E18: =SUM(E8:E17) -> 14373.44 | F18: =SUM(F8:F17) -> -15.2 | G18: =SUM(G8:G17) -> 0 | H18: =SUM(H8:H17) -> 0 | I18: =SUM(I8:I17) -> 1207.16
A19: Catering on the same day | B19: =SUM(D104) -> 0 | C19: =F104+E104 -> 0 | E19: =SUM(E46+F46-E47-F47) -> 0 | F19: =D19-B19 -> 0 | G19: =E19-C19 -> 0 | H19: =SUM(C118) -> 0 | I19: =(D19+E19+H19)*0.95/11 -> 0
A20: Smart App café
A21: Smart App catering
A22: Westend
A23: TOTAL | B23: =SUM(B3+B4+B5+B6+B7+B18+B19+B22) -> 3744.4 | C23: =SUM(C3+C4+C5+C6+C7+C18+C19+C20+C21+C22) -> 19168.91 | D23: =SUM(D3+D4+D5+D6+D7+D18+D19+D20+D21+D22)-3073-595.2 -> 61 | E23: =SUM(E3+E4+E5+E6+E7+E18+E19+E20+E21+E22) -> 19168.91 | F23: =SUM(F3+F4+F5+F6+F7+F18+F19+F20+F21+F22) -> -15.2 | G23: =SUM(G3+G4+G5+G6+G7+G18+G19+G20+G21+G22) -> 0 | H23: =SUM(H3+H4+H5+H6+H7+H18+H19+H20+H21+H22) -> 0 | I23: =SUM(I3+I4+I5+I6+I7+I18+I19+I20+I21+I22) -> 1593.73
A24: Cash | D24: 3
A25: INVOICES PAID Cash | B25: Total Inc GST | C25: use till coffee right only | E25: Banking details | G25: Amount deposited
A26: pendle meat 71572 | C26: 1359.7 | E26: Name of Staff | G26: Bank branch
A27: pendle meat 71573 | C27: 1713.3 | E27: Reciept | G27: Time | H27: :
A28: steglles 137626-3 | C28: 595.2
A29: SUPPLIER4 | H29: Today Total income | I29: =SUM(B23+C23+G23+F23+H23-I23) -> 21304.38
A30: SUPPLIER5 | D30: Credit Cards Reconcile | E30: Amex | F30: CR+DR | H30: TOTAL $ in SAFE | I30: =SUM(D23+'4th'!I30-'5th'!H25) -> 60.99
A31: SUPPLIER6 | D31: COFFEE THERAPY
A32: SUPPLIER7 | D32: HEALTHY FILLINGS
A33: SUPPLIER8 | D33: OUTPATIENT
A34: SUPPLIER9 | D34: COFFEE BOX
A35: SUPPLIER10 | D35: Green Organic
A36: SUPPLIER11 | D36: Till 1 Coffee Left
A37: SUPPLIER12 | D37: Till 2 Coffee Right
A38: SUPPLIER13 | D38: Till 3 Sushi
A39: SUPPLIER14 | D39: Till 4 Panine
A40: TOTAL Bills Paid Cash | B40: =SUM(B26:B39) -> 0 | D40: Till 5 Salad
...

Sheet 6th
A1: Zouki Westmead | G1: should be $0
A2: =SUM('5th'!A2+1) -> 45875 | B2: Cash Read | C2: CC Read | D2: Cash Collected | E2: Eftpos Collected | F2: +/- over under Cash | G2: +/- over under CC | H2: Acc/smart Cards | I2: GST Read
A3: COFFEE THERAPY | B3: 130.7 | C3: 704.53 | D3: 130.7 | E3: 704.53 | F3: =D3-B3 -> 0 | G3: =E3-C3 -> 0 | I3: 61.11
A4: HEALTHY FILLINGS | E4: =SUM(E32+F32) -> 0 | F4: =D4-B4 -> 0 | G4: =E4-C4 -> 0
A5: OUTPATIENT | B5: 248.6 | C5: 2521.6 | D5: 248.6 | E5: 2521.6 | F5: =D5-B5 -> 0 | G5: =E5-C5 -> 0 | I5: 195.35
A6: COFFEE BOX | B6: 219.8 | C6: 1215 | D6: =50+50+115+4.8 -> 219.8 | E6: 1215 | F6: =D6-B6 -> 0 | G6: =E6-C6 -> 0 | I6: 102.64
A7: Green Organic | B7: 160.5 | C7: 1047.1 | D7: 160.5 | E7: 1047.1 | F7: =D7-B7 -> 0 | G7: =E7-C7 -> 0
A8: Till 1 Coffee Left | B8: 766.9 | C8: 3536.51 | D8: =500+215+1.9+50 -> 766.9 | E8: 3536.51 | F8: =D8-B8 -> 0 | G8: =E8-C8 -> 0 | I8: 262.4
A9: Till 2 Coffee Right | B9: 421.4 | C9: 1676 | D9: 421.4 | E9: 1676 | F9: =D9-B9+B40 -> 0 | G9: =E9-C9 -> 0 | I9: 125.82
A10: Till 3 Sushi | E10: =SUM(E38+F38) -> 0 | F10: =D10-B10 -> 0 | G10: =E10-C10 -> 0
A11: Till 4 Panine | B11: 261.1 | C11: 2214.25 | D11: 261.1 | E11: 2214.25 | F11: =D11-B11 -> 0 | G11: =E11-C11 -> 0 | I11: 178.25
A12: Till 5 Salad | E12: =SUM(E40+F40) -> 0 | F12: =D12-B12 -> 0 | G12: =E12-C12 -> 0
A13: Till 6 Pizza | B13: 219.2 | C13: 564.74 | D13: 219.2 | E13: 564.74 | F13: =D13-B13 -> 0 | G13: =E13-C13 -> 0 | I13: 61.88
A14: Till 7 Kebab | B14: 166.1 | C14: 1377.93 | D14: 163.6 | E14: 1377.93 | F14: =D14-B14 -> -2.5 | G14: =E14-C14 -> 0 | I14: 134.41
A15: Till 8 Hot Food | B15: 109.9 | C15: 860.16 | D15: 109.9 | E15: 860.16 | F15: =D15-B15 -> 0 | G15: =E15-C15 -> 0 | I15: 83.99
A16: Till 9 Wok | B16: 1194.2 | C16: 5968.78 | D16: =700+5+450+35+4.2 -> 1194.2 | E16: 5968.78 | F16: =D16-B16 -> 0 | G16: =E16-C16 -> 0 | I16: 580
A17: Till 10 Juice Bar | B17: 301.2 | C17: 1033.23 | D17: 301.2 | E17: 1033.23 | F17: =D17-B17 -> 0 | G17: =E17-C17 -> 0 | I17: 0.55
A18: Main Cafe Total | B18: =SUM(B8:B17) -> 3440 | C18: =SUM(C8:C17) -> 17231.6 | D18: =SUM(D8:D17) -> 3437.5 | E18: =SUM(E8:E17) -> 17231.6 | F18: =SUM(F8:F17) -> -2.5 | G18: =SUM(G8:G17) -> 0 | H18: =SUM(H8:H17) -> 0 | I18: =SUM(I8:I17) -> 1427.3
A19: Catering on the same day | B19: =SUM(D104) -> 0 | C19: =F104+E104 -> 0 | E19: =SUM(E46+F46-E47-F47) -> 0 | F19: =D19-B19 -> 0 | G19: =E19-C19 -> 0 | H19: =SUM(C118) -> 0 | I19: =(D19+E19+H19)*0.95/11 -> 0
A20: Smart App café
A21: Smart App catering
A22: Westend
A23: TOTAL | B23: =SUM(B3+B4+B5+B6+B7+B18+B19+B22) -> 4199.6 | C23: =SUM(C3+C4+C5+C6+C7+C18+C19+C20+C21+C22) -> 22719.83 | D23: =SUM(D3+D4+D5+D6+D7+D18+D19+D20+D21+D22)-3685.7-25.2-418.7 -> 67.5 | E23: =SUM(E3+E4+E5+E6+E7+E18+E19+E20+E21+E22) -> 22719.83 | F23: =SUM(F3+F4+F5+F6+F7+F18+F19+F20+F21+F22) -> -2.5 | G23: =SUM(G3+G4+G5+G6+G7+G18+G19+G20+G21+G22) -> 0 | H23: =SUM(H3+H4+H5+H6+H7+H18+H19+H20+H21+H22) -> 0 | I23: =SUM(I3+I4+I5+I6+I7+I18+I19+I20+I21+I22) -> 1786.4
A24: Cash
A25: INVOICES PAID Cash | B25: Total Inc GST | C25: use till coffee right only | E25: Banking details | G25: Amount deposited
A26: pendle meat 71575 | C26: 3685.7 | E26: Name of Staff | G26: Bank branch
A27: coles | C27: 25.2 | E27: Reciept | G27: Time | H27: :
A28: patrickinv 246312 | C28: 418.7
A29: SUPPLIER4 | H29: Today Total income | I29: =SUM(B23+C23+G23+F23+H23-I23) -> 25130.53
A30: SUPPLIER5 | D30: Credit Cards Reconcile | E30: Amex | F30: CR+DR | H30: TOTAL $ in SAFE | I30: =SUM(D23+'5th'!I30-'6th'!H25) -> 128.49
A31: SUPPLIER6 | D31: COFFEE THERAPY
A32: SUPPLIER7 | D32: HEALTHY FILLINGS
A33: SUPPLIER8 | D33: OUTPATIENT
A34: SUPPLIER9 | D34: COFFEE BOX
A35: SUPPLIER10 | D35: Green Organic
A36: SUPPLIER11 | D36: Till 1 Coffee Left
A37: SUPPLIER12 | D37: Till 2 Coffee Right
A38: SUPPLIER13 | D38: Till 3 Sushi
A39: SUPPLIER14 | D39: Till 4 Panine
A40: TOTAL Bills Paid Cash | B40: =SUM(B26:B39) -> 0 | D40: Till 5 Salad
...

Sheet 7th
A1: Zouki Westmead | G1: should be $0
A2: =SUM('6th'!A2+1) -> 45876 | B2: Cash Read | C2: CC Read | D2: Cash Collected | E2: Eftpos Collected | F2: +/- over under Cash | G2: +/- over under CC | H2: Acc/smart Cards | I2: GST Read
A3: COFFEE THERAPY | B3: 127.2 | C3: 661.99 | D3: 107.4 | E3: 661.99 | F3: =D3-B3 -> -19.8 | G3: =E3-C3 -> 0 | I3: 58.83
A4: HEALTHY FILLINGS | E4: =SUM(E32+F32) -> 0 | F4: =D4-B4 -> 0 | G4: =E4-C4 -> 0
A5: OUTPATIENT | B5: 176.9 | C5: 2794.67 | D5: 176.9 | E5: 2794.67 | F5: =D5-B5 -> 0 | G5: =E5-C5 -> 0 | I5: 202.35
A6: COFFEE BOX | B6: 143.7 | C6: 1256.41 | D6: 143.7 | E6: 1256.41 | F6: =D6-B6 -> 0 | G6: =E6-C6 -> 0 | I6: 102.74
A7: Green Organic | B7: 261.4 | C7: 1013.89 | D7: 261.4 | E7: 1013.89 | F7: =D7-B7 -> 0 | G7: =E7-C7 -> 0 | I7: 85.09
A8: Till 1 Coffee Left | B8: 526.4 | C8: 3725.66 | D8: 526.4 | E8: 3725.66 | F8: =D8-B8 -> 0 | G8: =E8-C8 -> 0 | I8: 260.53
A9: Till 2 Coffee Right | B9: 380.7 | C9: 1755.84 | D9: 380.7 | E9: 1755.84 | F9: =D9-B9+B40 -> 0 | G9: =E9-C9 -> 0 | I9: 137.15
A10: Till 3 Sushi | E10: =SUM(E38+F38) -> 0 | F10: =D10-B10 -> 0 | G10: =E10-C10 -> 0
A11: Till 4 Panine | B11: 224.8 | C11: 2108.21 | D11: 224.8 | E11: 2108.21 | F11: =D11-B11 -> 0 | G11: =E11-C11 -> 0 | I11: 154.74
A12: Till 5 Salad | E12: =SUM(E40+F40) -> 0 | F12: =D12-B12 -> 0 | G12: =E12-C12 -> 0
A13: Till 6 Pizza | B13: 126 | C13: 648.11 | D13: 126 | E13: 648.11 | F13: =D13-B13 -> 0 | G13: =E13-C13 -> 0 | I13: 58.06
A14: Till 7 Kebab | B14: 181.5 | C14: 1213.19 | D14: 181.5 | E14: 1213.19 | F14: =D14-B14 -> 0 | G14: =E14-C14 -> 0 | I14: 123.99
A15: Till 8 Hot Food | B15: 227.5 | C15: 1177.54 | D15: 227.5 | E15: 1177.54 | F15: =D15-B15 -> 0 | G15: =E15-C15 -> 0 | I15: 120.94
A16: Till 9 Wok | B16: 941.5 | C16: 6461.96 | D16: =941.5 -> 941.5 | E16: 6461.96 | F16: =D16-B16 -> 0 | G16: =E16-C16 -> 0 | I16: 579.92
A17: Till 10 Juice Bar | B17: 218.7 | C17: 922.55 | D17: 218.7 | E17: 922.55 | F17: =D17-B17 -> 0 | G17: =E17-C17 -> 0 | I17: 0.18
A18: Main Cafe Total | B18: =SUM(B8:B17) -> 2827.1 | C18: =SUM(C8:C17) -> 18013.06 | D18: =SUM(D8:D17) -> 2827.1 | E18: =SUM(E8:E17) -> 18013.06 | F18: =SUM(F8:F17) -> 0 | G18: =SUM(G8:G17) -> 0 | H18: =SUM(H8:H17) -> 0 | I18: =SUM(I8:I17) -> 1435.51
A19: Catering on the same day | B19: =SUM(D104) -> 0 | C19: =F104+E104 -> 0 | E19: =SUM(E46+F46-E47-F47) -> 0 | F19: =D19-B19 -> 0 | G19: =E19-C19 -> 0 | H19: =SUM(C118) -> 0 | I19: =(D19+E19+H19)*0.95/11 -> 0
A20: Smart App café
A21: Smart App catering
A22: Westend
A23: TOTAL | B23: =SUM(B3+B4+B5+B6+B7+B18+B19+B22) -> 3536.3 | C23: =SUM(C3+C4+C5+C6+C7+C18+C19+C20+C21+C22) -> 23740.02 | D23: =SUM(D3+D4+D5+D6+D7+D18+D19+D20+D21+D22)-1970-1341.7 -> 204.8 | E23: =SUM(E3+E4+E5+E6+E7+E18+E19+E20+E21+E22) -> 23740.02 | F23: =SUM(F3+F4+F5+F6+F7+F18+F19+F20+F21+F22) -> -19.8 | G23: =SUM(G3+G4+G5+G6+G7+G18+G19+G20+G21+G22) -> 0 | H23: =SUM(H3+H4+H5+H6+H7+H18+H19+H20+H21+H22) -> 0 | I23: =SUM(I3+I4+I5+I6+I7+I18+I19+I20+I21+I22) -> 1884.52
A24: Cash
A25: INVOICES PAID Cash | B25: Total Inc GST | C25: use till coffee right only | E25: Banking details | G25: Amount deposited
A26: patricks inv 245722 | C26: 1967.9 | E26: Name of Staff | G26: Bank branch
A27: patricks inv 246031 | C27: 1341.7 | E27: Reciept | G27: Time | H27: :
A28: SUPPLIER3
A29: SUPPLIER4 | H29: Today Total income | I29: =SUM(B23+C23+G23+F23+H23-I23) -> 25372
A30: SUPPLIER5 | D30: Credit Cards Reconcile | E30: Amex | F30: CR+DR | H30: TOTAL $ in SAFE | I30: =SUM(D23+'6th'!I30-'7th'!H25) -> 333.29
A31: SUPPLIER6 | D31: COFFEE THERAPY
A32: SUPPLIER7 | D32: HEALTHY FILLINGS
A33: SUPPLIER8 | D33: OUTPATIENT
A34: SUPPLIER9 | D34: COFFEE BOX
A35: SUPPLIER10 | D35: Green Organic
A36: SUPPLIER11 | D36: Till 1 Coffee Left
A37: SUPPLIER12 | D37: Till 2 Coffee Right
A38: SUPPLIER13 | D38: Till 3 Sushi
A39: SUPPLIER14 | D39: Till 4 Panine
A40: TOTAL Bills Paid Cash | B40: =SUM(B26:B39) -> 0 | D40: Till 5 Salad
...

Sheet 8th
A1: Zouki Westmead | G1: should be $0
A2: =SUM('7th'!A2+1) -> 45877 | B2: Cash Read | C2: CC Read | D2: Cash Collected | E2: Eftpos Collected | F2: +/- over under Cash | G2: +/- over under CC | H2: Acc/smart Cards | I2: GST Read
A3: COFFEE THERAPY | B3: 65.7 | C3: 475.12 | D3: 65.7 | E3: 475.12 | F3: =D3-B3 -> 0 | G3: =E3-C3 -> 0 | I3: 40.36
A4: HEALTHY FILLINGS | E4: =SUM(E32+F32) -> 0 | F4: =D4-B4 -> 0 | G4: =E4-C4 -> 0
A5: OUTPATIENT | B5: 136.7 | C5: 2495.6 | D5: 136.7 | E5: 2495.6 | F5: =D5-B5 -> 0 | G5: =E5-C5 -> 0 | I5: 190.34
A6: COFFEE BOX | B6: 138.6 | C6: 877.43 | D6: 138.6 | E6: 877.43 | F6: =D6-B6 -> 0 | G6: =E6-C6 -> 0 | I6: 78.17
A7: Green Organic | B7: 211.6 | C7: 863.96 | D7: 211.6 | E7: 863.96 | F7: =D7-B7 -> 0 | G7: =E7-C7 -> 0 | I7: 75.49
A8: Till 1 Coffee Left | B8: 573.1 | C8: 3607.46 | D8: 573.1 | E8: 3607.46 | F8: =D8-B8 -> 0 | G8: =E8-C8 -> 0 | I8: 239.08
A9: Till 2 Coffee Right | B9: 264.4 | C9: 1679.72 | D9: =264 -> 264 | E9: 1679.72 | F9: =D9-B9+B40 -> -0.4 | G9: =E9-C9 -> 0 | I9: 120.65
A10: Till 3 Sushi | E10: =SUM(E38+F38) -> 0 | F10: =D10-B10 -> 0 | G10: =E10-C10 -> 0
A11: Till 4 Panine | B11: 245.8 | C11: 1900.22 | D11: 245.8 | E11: 1900.22 | F11: =D11-B11 -> 0 | G11: =E11-C11 -> 0 | I11: 151.5
A12: Till 5 Salad | E12: =SUM(E40+F40) -> 0 | F12: =D12-B12 -> 0 | G12: =E12-C12 -> 0
A13: Till 6 Pizza | B13: 139.3 | C13: 751.54 | D13: 139.3 | E13: 751.54 | F13: =D13-B13 -> 0 | G13: =E13-C13 -> 0 | I13: 62.41
A14: Till 7 Kebab | B14: 162.6 | C14: 1247.01 | D14: 162.6 | E14: 1247.01 | F14: =D14-B14 -> 0 | G14: =E14-C14 -> 0 | I14: 126.55
A15: Till 8 Hot Food | B15: 79.3 | C15: 888.47 | D15: 79.3 | E15: 888.47 | F15: =D15-B15 -> 0 | G15: =E15-C15 -> 0 | I15: 81.91
A16: Till 9 Wok | B16: 749.8 | C16: 5993.66 | D16: 749.8 | E16: 5993.66 | F16: =D16-B16 -> 0 | G16: =E16-C16 -> 0 | I16: 535.38
A17: Till 10 Juice Bar | B17: 137.9 | C17: 829.38 | D17: 137.9 | E17: 829.38 | F17: =D17-B17 -> 0 | G17: =E17-C17 -> 0 | I17: 1.17
A18: Main Cafe Total | B18: =SUM(B8:B17) -> 2352.2 | C18: =SUM(C8:C17) -> 16897.46 | D18: =SUM(D8:D17) -> 2351.8 | E18: =SUM(E8:E17) -> 16897.46 | F18: =SUM(F8:F17) -> -0.4 | G18: =SUM(G8:G17) -> 0 | H18: =SUM(H8:H17) -> 0 | I18: =SUM(I8:I17) -> 1318.65
A19: Catering on the same day | B19: =SUM(D104) -> 0 | C19: =F104+E104 -> 0 | E19: =SUM(E46+F46-E47-F47) -> 0 | F19: =D19-B19 -> 0 | G19: =E19-C19 -> 0 | H19: =SUM(C118) -> 0 | I19: =(D19+E19+H19)*0.95/11 -> 0
A20: Smart App café
A21: Smart App catering
A22: Westend
A23: TOTAL | B23: =SUM(B3+B4+B5+B6+B7+B18+B19+B22) -> 2904.8 | C23: =SUM(C3+C4+C5+C6+C7+C18+C19+C20+C21+C22) -> 21609.57 | D23: =SUM(D3+D4+D5+D6+D7+D18+D19+D20+D21+D22)-1310.7-1413.7-125.8 -> 54.2 | E23: =SUM(E3+E4+E5+E6+E7+E18+E19+E20+E21+E22) -> 21609.57 | F23: =SUM(F3+F4+F5+F6+F7+F18+F19+F20+F21+F22) -> -0.4 | G23: =SUM(G3+G4+G5+G6+G7+G18+G19+G20+G21+G22) -> 0 | H23: =SUM(H3+H4+H5+H6+H7+H18+H19+H20+H21+H22) -> 0 | I23: =SUM(I3+I4+I5+I6+I7+I18+I19+I20+I21+I22) -> 1703.01
A24: Cash
A25: INVOICES PAID Cash | B25: Total Inc GST | C25: use till coffee right only | E25: Banking details | G25: Amount deposited
A26: patricks inv 246404 | C26: 1310.7 | E26: Name of Staff | G26: Bank branch
A27: patrickinv 246658 | C27: 1413.8 | E27: Reciept | G27: Time | H27: :
A28: steggles 138123-3 | C28: 125.8
A29: SUPPLIER4 | H29: Today Total income | I29: =SUM(B23+C23+G23+F23+H23-I23) -> 22810.96
A30: SUPPLIER5 | D30: Credit Cards Reconcile | E30: Amex | F30: CR+DR | H30: TOTAL $ in SAFE | I30: =SUM(D23+'7th'!I30-'8th'!H25) -> 387.49
A31: SUPPLIER6 | D31: COFFEE THERAPY
A32: SUPPLIER7 | D32: HEALTHY FILLINGS
A33: SUPPLIER8 | D33: OUTPATIENT
A34: SUPPLIER9 | D34: COFFEE BOX
A35: SUPPLIER10 | D35: Green Organic
A36: SUPPLIER11 | D36: Till 1 Coffee Left
A37: SUPPLIER12 | D37: Till 2 Coffee Right
A38: SUPPLIER13 | D38: Till 3 Sushi
A39: SUPPLIER14 | D39: Till 4 Panine
A40: TOTAL Bills Paid Cash | B40: =SUM(B26:B39) -> 0 | D40: Till 5 Salad
...

Sheet 9th
A1: Zouki Westmead | G1: should be $0
A2: =SUM('8th'!A2+1) -> 45878 | B2: Cash Read | C2: CC Read | D2: Cash Collected | E2: Eftpos Collected | F2: +/- over under Cash | G2: +/- over under CC | H2: Acc/smart Cards | I2: GST Read
A3: COFFEE THERAPY | E3: =SUM(E31+F31) -> 0 | F3: =D3-B3 -> 0 | G3: =E3-C3 -> 0
A4: HEALTHY FILLINGS | E4: =SUM(E32+F32) -> 0 | F4: =D4-B4 -> 0 | G4: =E4-C4 -> 0
A5: OUTPATIENT | E5: =SUM(E33+F33) -> 0 | F5: =D5-B5 -> 0 | G5: =E5-C5 -> 0
A6: COFFEE BOX | E6: =SUM(E34+F34) -> 0 | F6: =D6-B6 -> 0 | G6: =E6-C6 -> 0
A7: Green Organic | E7: =SUM(E35+F35) -> 0 | F7: =D7-B7 -> 0 | G7: =E7-C7 -> 0
A8: Till 1 Coffee Left | B8: 538 | C8: 3419.88 | D8: =538 -> 538 | E8: 3419.88 | F8: =D8-B8 -> 0 | G8: =E8-C8 -> 0 | I8: 221.76
A9: Till 2 Coffee Right | E9: =SUM(E37+F37) -> 0 | F9: =D9-B9+B40 -> 0 | G9: =E9-C9 -> 0
A10: Till 3 Sushi | E10: =SUM(E38+F38) -> 0 | F10: =D10-B10 -> 0 | G10: =E10-C10 -> 0
A11: Till 4 Panine | E11: =SUM(E39+F39) -> 0 | F11: =D11-B11 -> 0 | G11: =E11-C11 -> 0
A12: Till 5 Salad | E12: =SUM(E40+F40) -> 0 | F12: =D12-B12 -> 0 | G12: =E12-C12 -> 0
A13: Till 6 Pizza | E13: =SUM(E41+F41) -> 0 | F13: =D13-B13 -> 0 | G13: =E13-C13 -> 0
A14: Till 7 Kebab | B14: 47.7 | C14: 602.6 | D14: 47.7 | E14: 602.6 | F14: =D14-B14 -> 0 | G14: =E14-C14 -> 0 | I14: 57.27
A15: Till 8 Hot Food | E15: =SUM(E43+F43) -> 0 | F15: =D15-B15 -> 0 | G15: =E15-C15 -> 0
A16: Till 9 Wok | B16: 525.4 | C16: 2592.64 | D16: 525.4 | E16: 2592.64 | F16: =D16-B16 -> 0 | G16: =E16-C16 -> 0 | I16: 202.6
A17: Till 10 Juice Bar | E17: =SUM(E45+F45) -> 0 | F17: =D17-B17 -> 0 | G17: =E17-C17 -> 0
A18: Main Cafe Total | B18: =SUM(B8:B17) -> 1111.1 | C18: =SUM(C8:C17) -> 6615.12 | D18: =SUM(D8:D17) -> 1111.1 | E18: =SUM(E8:E17) -> 6615.12 | F18: =SUM(F8:F17) -> 0 | G18: =SUM(G8:G17) -> 0 | H18: =SUM(H8:H17) -> 0 | I18: =SUM(I8:I17) -> 481.63
A19: Catering on the same day | B19: =SUM(D104) -> 0 | C19: =F104+E104 -> 0 | E19: =SUM(E46+F46-E47-F47) -> 0 | F19: =D19-B19 -> 0 | G19: =E19-C19 -> 0 | H19: =SUM(C118) -> 0 | I19: =(D19+E19+H19)*0.95/11 -> 0
A20: Smart App café
A21: Smart App catering
A22: Westend
A23: TOTAL | B23: =SUM(B3+B4+B5+B6+B7+B18+B19+B22) -> 1111.1 | C23: =SUM(C3+C4+C5+C6+C7+C18+C19+C20+C21+C22) -> 6615.12 | D23: =SUM(D3+D4+D5+D6+D7+D18+D19+D20+D21+D22)-1111.1 -> 0 | E23: =SUM(E3+E4+E5+E6+E7+E18+E19+E20+E21+E22) -> 6615.12 | F23: =SUM(F3+F4+F5+F6+F7+F18+F19+F20+F21+F22) -> 0 | G23: =SUM(G3+G4+G5+G6+G7+G18+G19+G20+G21+G22) -> 0 | H23: =SUM(H3+H4+H5+H6+H7+H18+H19+H20+H21+H22) -> 0 | I23: =SUM(I3+I4+I5+I6+I7+I18+I19+I20+I21+I22) -> 481.63
A24: Cash | D24: p
A25: INVOICES PAID Cash | B25: Total Inc GST | C25: use till coffee right only | E25: Banking details | G25: Amount deposited
A26: patrickinv 247039 | C26: 1111.1 | E26: Name of Staff | G26: Bank branch
A27: SUPPLIER2 | E27: Reciept | G27: Time | H27: :
A28: SUPPLIER3
A29: SUPPLIER4 | H29: Today Total income | I29: =SUM(B23+C23+G23+F23+H23-I23) -> 7244.59
A30: SUPPLIER5 | D30: Credit Cards Reconcile | E30: Amex | F30: CR+DR | H30: TOTAL $ in SAFE | I30: =SUM(D23+'8th'!I30-'9th'!H25) -> 387.49
A31: SUPPLIER6 | D31: COFFEE THERAPY
A32: SUPPLIER7 | D32: HEALTHY FILLINGS
A33: SUPPLIER8 | D33: OUTPATIENT
A34: SUPPLIER9 | D34: COFFEE BOX
A35: SUPPLIER10 | D35: Green Organic
A36: SUPPLIER11 | D36: Till 1 Coffee Left
A37: SUPPLIER12 | D37: Till 2 Coffee Right
A38: SUPPLIER13 | D38: Till 3 Sushi
A39: SUPPLIER14 | D39: Till 4 Panine
A40: TOTAL Bills Paid Cash | B40: =SUM(B26:B39) -> 0 | D40: Till 5 Salad
...

Sheet 10th
A1: Zouki Westmead | G1: should be $0
A2: =SUM('9th'!A2+1) -> 45879 | B2: Cash Read | C2: CC Read | D2: Cash Collected | E2: Eftpos Collected | F2: +/- over under Cash | G2: +/- over under CC | H2: Acc/smart Cards | I2: GST Read
A3: COFFEE THERAPY | E3: =SUM(E31+F31) -> 0 | F3: =D3-B3 -> 0 | G3: =E3-C3 -> 0
A4: HEALTHY FILLINGS | E4: =SUM(E32+F32) -> 0 | F4: =D4-B4 -> 0 | G4: =E4-C4 -> 0
A5: OUTPATIENT | E5: =SUM(E33+F33) -> 0 | F5: =D5-B5 -> 0 | G5: =E5-C5 -> 0
A6: COFFEE BOX | E6: =SUM(E34+F34) -> 0 | F6: =D6-B6 -> 0 | G6: =E6-C6 -> 0
A7: Green Organic | E7: =SUM(E35+F35) -> 0 | F7: =D7-B7 -> 0 | G7: =E7-C7 -> 0
A8: Till 1 Coffee Left | B8: 613.8 | C8: 3043.55 | D8: 614 | E8: 3043.55 | F8: =D8-B8 -> 0.2 | G8: =E8-C8 -> 0 | I8: 200.92
A9: Till 2 Coffee Right | E9: =SUM(E37+F37) -> 0 | F9: =D9-B9+B40 -> 0 | G9: =E9-C9 -> 0
A10: Till 3 Sushi | E10: =SUM(E38+F38) -> 0 | F10: =D10-B10 -> 0 | G10: =E10-C10 -> 0
A11: Till 4 Panine | E11: =SUM(E39+F39) -> 0 | F11: =D11-B11 -> 0 | G11: =E11-C11 -> 0
A12: Till 5 Salad | E12: =SUM(E40+F40) -> 0 | F12: =D12-B12 -> 0 | G12: =E12-C12 -> 0
A13: Till 6 Pizza | E13: =SUM(E41+F41) -> 0 | F13: =D13-B13 -> 0 | G13: =E13-C13 -> 0
A14: Till 7 Kebab | B14: 111.3 | C14: 753.48 | D14: 111.3 | E14: 753.48 | F14: =D14-B14 -> 0 | G14: =E14-C14 -> 0 | I14: 75.6
A15: Till 8 Hot Food | B15: 45.6 | C15: 359.04 | D15: 45.6 | E15: 359.04 | F15: =D15-B15 -> 0 | G15: =E15-C15 -> 0 | I15: 28.03
A16: Till 9 Wok | B16: 381.6 | C16: 2163.41 | D16: 381.6 | E16: 2163.41 | F16: =D16-B16 -> 0 | G16: =E16-C16 -> 0 | I16: 168.3
A17: Till 10 Juice Bar | E17: =SUM(E45+F45) -> 0 | F17: =D17-B17 -> 0 | G17: =E17-C17 -> 0
A18: Main Cafe Total | B18: =SUM(B8:B17) -> 1152.3 | C18: =SUM(C8:C17) -> 6319.48 | D18: =SUM(D8:D17) -> 1152.5 | E18: =SUM(E8:E17) -> 6319.48 | F18: =SUM(F8:F17) -> 0.2 | G18: =SUM(G8:G17) -> 0 | H18: =SUM(H8:H17) -> 0 | I18: =SUM(I8:I17) -> 472.85
A19: Catering on the same day | B19: =SUM(D104) -> 0 | C19: =F104+E104 -> 0 | E19: =SUM(E46+F46-E47-F47) -> 0 | F19: =D19-B19 -> 0 | G19: =E19-C19 -> 0 | H19: =SUM(C118) -> 0 | I19: =(D19+E19+H19)*0.95/11 -> 0
A20: Smart App café
A21: Smart App catering
A22: Westend
A23: TOTAL | B23: =SUM(B3+B4+B5+B6+B7+B18+B19+B22) -> 1152.3 | C23: =SUM(C3+C4+C5+C6+C7+C18+C19+C20+C21+C22) -> 6319.48 | D23: =SUM(D3+D4+D5+D6+D7+D18+D19+D20+D21+D22)-491.2-580 -> 81.3 | E23: =SUM(E3+E4+E5+E6+E7+E18+E19+E20+E21+E22) -> 6319.48 | F23: =SUM(F3+F4+F5+F6+F7+F18+F19+F20+F21+F22) -> 0.2 | G23: =SUM(G3+G4+G5+G6+G7+G18+G19+G20+G21+G22) -> 0 | H23: =SUM(H3+H4+H5+H6+H7+H18+H19+H20+H21+H22) -> 0 | I23: =SUM(I3+I4+I5+I6+I7+I18+I19+I20+I21+I22) -> 472.85
A24: Cash
A25: INVOICES PAID Cash | B25: Total Inc GST | C25: use till coffee right only | E25: Banking details | G25: Amount deposited
A26: patrickinv 247039 | C26: 491.2 | E26: Name of Staff | G26: Bank branch
A27: steggles 138079-3 | C27: 580 | E27: Reciept | G27: Time | H27: :
A29: SUPPLIER4 | H29: Today Total income | I29: =SUM(B23+C23+G23+F23+H23-I23) -> 6999.13
A30: SUPPLIER5 | D30: Credit Cards Reconcile | E30: Amex | F30: CR+DR | H30: TOTAL $ in SAFE | I30: =SUM(D23+'9th'!I30-'10th'!H25) -> 468.79
A31: SUPPLIER6 | D31: COFFEE THERAPY
A32: SUPPLIER7 | D32: HEALTHY FILLINGS
A33: SUPPLIER8 | D33: OUTPATIENT
A34: SUPPLIER9 | D34: COFFEE BOX
A35: SUPPLIER10 | D35: Green Organic
A36: SUPPLIER11 | D36: Till 1 Coffee Left
A37: SUPPLIER12 | D37: Till 2 Coffee Right
A38: SUPPLIER13 | D38: Till 3 Sushi
A39: SUPPLIER14 | D39: Till 4 Panine
A40: TOTAL Bills Paid Cash | B40: =SUM(B26:B39) -> 0 | D40: Till 5 Salad
D41: Till 6 Pizza
...

Sheet 11th
A1: Zouki Westmead | G1: should be $0
A2: =SUM('10th'!A2+1) -> 45880 | B2: Cash Read | C2: CC Read | D2: Cash Collected | E2: Eftpos Collected | F2: +/- over under Cash | G2: +/- over under CC | H2: Acc/smart Cards | I2: GST Read
A3: COFFEE THERAPY | B3: 138.9 | C3: 546.93 | D3: 138.9 | E3: 546.93 | F3: =D3-B3 -> 0 | G3: =E3-C3 -> 0 | I3: 51.14
A4: HEALTHY FILLINGS | E4: =SUM(E32+F32) -> 0 | F4: =D4-B4 -> 0 | G4: =E4-C4 -> 0
A5: OUTPATIENT | B5: 207.6 | C5: 2511.15 | D5: 207.6 | E5: 2511.15 | F5: =D5-B5 -> 0 | G5: =E5-C5 -> 0 | I5: 188.66
A6: COFFEE BOX | B6: 123.3 | C6: 963.96 | D6: =123.3 -> 123.3 | E6: 963.96 | F6: =D6-B6 -> 0 | G6: =E6-C6 -> 0 | I6: 78.94
A7: Green Organic | B7: 133.9 | C7: 794.6 | D7: 133.9 | E7: 794.6 | F7: =D7-B7 -> 0 | G7: =E7-C7 -> 0 | I7: 59.83
A8: Till 1 Coffee Left | B8: 484.6 | C8: 3528.4 | D8: =300+160+4.6+20 -> 484.6 | E8: 3528.4 | F8: =D8-B8 -> 0 | G8: =E8-C8 -> 0 | I8: 248.15
A9: Till 2 Coffee Right | B9: 196.3 | C9: 1723.09 | D9: 196.3 | E9: 1723.09 | F9: =D9-B9+B40 -> 175 | G9: =E9-C9 -> 0 | I9: 124.63
A10: Till 3 Sushi | E10: =SUM(E38+F38) -> 0 | F10: =D10-B10 -> 0 | G10: =E10-C10 -> 0
A11: Till 4 Panine | B11: 196 | C11: 1801.72 | D11: 196 | E11: 1801.72 | F11: =D11-B11 -> 0 | G11: =E11-C11 -> 0 | I11: 143.26
A12: Till 5 Salad | E12: =SUM(E40+F40) -> 0 | F12: =D12-B12 -> 0 | G12: =E12-C12 -> 0
A13: Till 6 Pizza | B13: 94.1 | C13: 599.41 | D13: 94.1 | E13: 599.41 | F13: =D13-B13 -> 0 | G13: =E13-C13 -> 0 | I13: 51.12
A14: Till 7 Kebab | B14: 185 | C14: 1272.16 | D14: =50+120+15 -> 185 | E14: 1272.16 | F14: =D14-B14 -> 0 | G14: =E14-C14 -> 0 | I14: 130.16
A15: Till 8 Hot Food | B15: 73.6 | C15: 766.43 | D15: 73.6 | E15: 766.43 | F15: =D15-B15 -> 0 | G15: =E15-C15 -> 0 | I15: 74.66
A16: Till 9 Wok | B16: 1011 | C16: 5395.31 | D16: =800+100+110+1.7 -> 1011.7 | E16: 5395.31 | F16: =D16-B16 -> 0.7 | G16: =E16-C16 -> 0 | I16: 533.68
A17: Till 10 Juice Bar | B17: 111.1 | C17: 579.19 | D17: 120 | E17: 579.19 | F17: =D17-B17 -> 8.9 | G17: =E17-C17 -> 0 | I17: 1.08
A18: Main Cafe Total | B18: =SUM(B8:B17) -> 2351.7 | C18: =SUM(C8:C17) -> 15665.71 | D18: =SUM(D8:D17) -> 2361.3 | E18: =SUM(E8:E17) -> 15665.71 | F18: =SUM(F8:F17) -> 184.6 | G18: =SUM(G8:G17) -> 0 | H18: =SUM(H8:H17) -> 0 | I18: =SUM(I8:I17) -> 1306.74
A19: Catering on the same day | B19: =SUM(D104) -> 0 | C19: =F104+E104 -> 0 | E19: =SUM(E46+F46-E47-F47) -> 0 | F19: =D19-B19 -> 0 | G19: =E19-C19 -> 0 | H19: =SUM(C118) -> 0 | I19: =(D19+E19+H19)*0.95/11 -> 0
A20: Smart App café
A21: Smart App catering
A22: Westend
A23: TOTAL | B23: =SUM(B3+B4+B5+B6+B7+B18+B19+B22) -> 2955.4 | C23: =SUM(C3+C4+C5+C6+C7+C18+C19+C20+C21+C22) -> 20482.35 | D23: =SUM(D3+D4+D5+D6+D7+D18+D19+D20+D21+D22)-2965 -> 0 | E23: =SUM(E3+E4+E5+E6+E7+E18+E19+E20+E21+E22) -> 20482.35 | F23: =SUM(F3+F4+F5+F6+F7+F18+F19+F20+F21+F22) -> 184.6 | G23: =SUM(G3+G4+G5+G6+G7+G18+G19+G20+G21+G22) -> 0 | H23: =SUM(H3+H4+H5+H6+H7+H18+H19+H20+H21+H22) -> 0 | I23: =SUM(I3+I4+I5+I6+I7+I18+I19+I20+I21+I22) -> 1685.31
A24: Cash
A25: INVOICES PAID Cash | B25: Total Inc GST | C25: use till coffee right only | E25: Banking details | G25: Amount deposited
A26: vodafone | B26: 175 | E26: Name of Staff | G26: Bank branch
A27: elite | C27: 2965 | E27: Reciept | G27: Time | H27: :
A28: SUPPLIER3
A29: SUPPLIER4 | H29: Today Total income | I29: =SUM(B23+C23+G23+F23+H23-I23) -> 21937.04
A30: SUPPLIER5 | D30: Credit Cards Reconcile | E30: Amex | F30: CR+DR | H30: TOTAL $ in SAFE | I30: =SUM(D23+'10th'!I30-'11th'!H25) -> 468.79
A31: SUPPLIER6 | D31: COFFEE THERAPY
A32: SUPPLIER7 | D32: HEALTHY FILLINGS
A33: SUPPLIER8 | D33: OUTPATIENT
A34: SUPPLIER9 | D34: COFFEE BOX
A35: SUPPLIER10 | D35: Green Organic
A36: SUPPLIER11 | D36: Till 1 Coffee Left
A37: SUPPLIER12 | D37: Till 2 Coffee Right
A38: SUPPLIER13 | D38: Till 3 Sushi
A39: SUPPLIER14 | D39: Till 4 Panine
A40: TOTAL Bills Paid Cash | B40: =SUM(B26:B39) -> 175 | D40: Till 5 Salad
...

Sheet 12th
A1: Zouki Westmead | G1: should be $0
A2: =SUM('11th'!A2+1) -> 45881 | B2: Cash Read | C2: CC Read | D2: Cash Collected | E2: Eftpos Collected | F2: +/- over under Cash | G2: +/- over under CC | H2: Acc/smart Cards | I2: GST Read
A3: COFFEE THERAPY | B3: 140.1 | C3: 754.61 | D3: 140.1 | E3: 754.61 | F3: =D3-B3 -> 0 | G3: =E3-C3 -> 0 | I3: 64.37
A4: HEALTHY FILLINGS | E4: =SUM(E32+F32) -> 0 | F4: =D4-B4 -> 0 | G4: =E4-C4 -> 0
A5: OUTPATIENT | B5: 257.8 | C5: 2371.1 | D5: 257.8 | E5: 2371.1 | F5: =D5-B5 -> 0 | G5: =E5-C5 -> 0 | I5: 192.99
A6: COFFEE BOX | B6: 148.1 | C6: 939.6 | D6: 148.1 | E6: 939.6 | F6: =D6-B6 -> 0 | G6: =E6-C6 -> 0 | I6: 76.02
A7: Green Organic | B7: 159.6 | C7: 843.16 | D7: 159.6 | E7: 843.16 | F7: =D7-B7 -> 0 | G7: =E7-C7 -> 0 | I7: 69.69
A8: Till 1 Coffee Left | B8: 703.1 | C8: 3041.74 | D8: =703.1 -> 703.1 | E8: 3041.74 | F8: =D8-B8 -> 0 | G8: =E8-C8 -> 0 | I8: 226.07
A9: Till 2 Coffee Right | B9: 304.2 | C9: 1855.73 | D9: =304.5 -> 304.5 | E9: 1855.73 | F9: =D9-B9+B40 -> 0.3 | G9: =E9-C9 -> 0 | I9: 128.71
A10: Till 3 Sushi | E10: =SUM(E38+F38) -> 0 | F10: =D10-B10 -> 0 | G10: =E10-C10 -> 0
A11: Till 4 Panine | B11: 253 | C11: 1932.1 | D11: 253 | E11: 1932.71 | F11: =D11-B11 -> 0 | G11: =E11-C11 -> 0.61 | I11: 150.33
A12: Till 5 Salad | E12: =SUM(E40+F40) -> 0 | F12: =D12-B12 -> 0 | G12: =E12-C12 -> 0
A13: Till 6 Pizza | B13: 144.3 | C13: 770.75 | D13: 144.3 | E13: 770.75 | F13: =D13-B13 -> 0 | G13: =E13-C13 -> 0 | I13: 68.53
A14: Till 7 Kebab | B14: 165.8 | C14: 1033.48 | D14: 183 | E14: 1033.48 | F14: =D14-B14 -> 17.2 | G14: =E14-C14 -> 0
A15: Till 8 Hot Food | B15: 72.6 | C15: 1150.25 | D15: 71.4 | E15: 1150.25 | F15: =D15-B15 -> -1.2 | G15: =E15-C15 -> 0 | I15: 108.39
A16: Till 9 Wok | B16: 1017.2 | C16: 5380.67 | D16: 1017.2 | E16: 5380.67 | F16: =D16-B16 -> 0 | G16: =E16-C16 -> 0 | I16: 522.42
A17: Till 10 Juice Bar | B17: 217 | C17: 757.88 | D17: 218.7 | E17: 757.88 | F17: =D17-B17 -> 1.7 | G17: =E17-C17 -> 0 | I17: 2.35
A18: Main Cafe Total | B18: =SUM(B8:B17) -> 2877.2 | C18: =SUM(C8:C17) -> 15922.6 | D18: =SUM(D8:D17) -> 2895.2 | E18: =SUM(E8:E17) -> 15923.21 | F18: =SUM(F8:F17) -> 18 | G18: =SUM(G8:G17) -> 0.61 | H18: =SUM(H8:H17) -> 0 | I18: =SUM(I8:I17) -> 1206.8
A19: Catering on the same day | B19: =SUM(D104) -> 0 | C19: =F104+E104 -> 0 | E19: =SUM(E46+F46-E47-F47) -> 0 | F19: =D19-B19 -> 0 | G19: =E19-C19 -> 0 | H19: =SUM(C118) -> 0 | I19: =(D19+E19+H19)*0.95/11 -> 0
A20: Smart App café
A21: Smart App catering
A22: Westend
A23: TOTAL | B23: =SUM(B3+B4+B5+B6+B7+B18+B19+B22) -> 3582.8 | C23: =SUM(C3+C4+C5+C6+C7+C18+C19+C20+C21+C22) -> 20831.07 | D23: =SUM(D3+D4+D5+D6+D7+D18+D19+D20+D21+D22)-1381.75-745.8-720-496-156-70 -> 31.25 | E23: =SUM(E3+E4+E5+E6+E7+E18+E19+E20+E21+E22) -> 20831.68 | F23: =SUM(F3+F4+F5+F6+F7+F18+F19+F20+F21+F22) -> 18 | G23: =SUM(G3+G4+G5+G6+G7+G18+G19+G20+G21+G22) -> 0.61 | H23: =SUM(H3+H4+H5+H6+H7+H18+H19+H20+H21+H22) -> 0 | I23: =SUM(I3+I4+I5+I6+I7+I18+I19+I20+I21+I22) -> 1609.87
A24: Cash
A25: INVOICES PAID Cash | B25: Total Inc GST | C25: use till coffee right only | E25: Banking details | G25: Amount deposited
A26: pendle meat71578 | C26: 1381.75 | E26: Name of Staff | G26: Bank branch
A27: steggles 06589-4 | C27: 745.8 | E27: Reciept | G27: Time | H27: :
A28: posh inv 279431 | C28: 718.15
A29: patrickinb 245358 | C29: 496 | H29: Today Total income | I29: =SUM(B23+C23+G23+F23+H23-I23) -> 22822.61
A30: qantas | C30: 156 | D30: Credit Cards Reconcile | E30: Amex | F30: CR+DR | H30: TOTAL $ in SAFE | I30: =SUM(D23+'11th'!I30-'12th'!H25) -> 500.04
A31: jetstar | C31: 70 | D31: COFFEE THERAPY
A32: SUPPLIER7 | D32: HEALTHY FILLINGS
A33: SUPPLIER8 | D33: OUTPATIENT
A34: SUPPLIER9 | D34: COFFEE BOX
A35: SUPPLIER10 | D35: Green Organic
A36: SUPPLIER11 | D36: Till 1 Coffee Left
A37: SUPPLIER12 | D37: Till 2 Coffee Right
A38: SUPPLIER13 | D38: Till 3 Sushi
A39: SUPPLIER14 | D39: Till 4 Panine
A40: TOTAL Bills Paid Cash | B40: =SUM(B26:B39) -> 0 | D40: Till 5 Salad
...

Sheet 13th
A1: Zouki Westmead | G1: should be $0
A2: =SUM('12th'!A2+1) -> 45882 | B2: Cash Read | C2: CC Read | D2: Cash Collected | E2: Eftpos Collected | F2: +/- over under Cash | G2: +/- over under CC | H2: Acc/smart Cards | I2: GST Read
A3: COFFEE THERAPY | B3: 99.2 | C3: 769.87 | D3: 100 | E3: 767.87 | F3: =D3-B3 -> 0.8 | G3: =E3-C3 -> -2 | I3: 61.97
A4: HEALTHY FILLINGS | E4: =SUM(E32+F32) -> 0 | F4: =D4-B4 -> 0 | G4: =E4-C4 -> 0
A5: OUTPATIENT | B5: 378.9 | C5: 2230.71 | D5: 377 | E5: 2230.71 | F5: =D5-B5 -> -1.9 | G5: =E5-C5 -> 0 | I5: 186.82
A6: COFFEE BOX | B6: 250.2 | C6: 1219.3 | D6: 250.2 | E6: 1219.3 | F6: =D6-B6 -> 0 | G6: =E6-C6 -> 0 | I6: 106.16
A7: Green Organic | B7: 100.2 | C7: 941.98 | D7: 100.2 | E7: 941.98 | F7: =D7-B7 -> 0 | G7: =E7-C7 -> 0 | I7: 67.57
A8: Till 1 Coffee Left | B8: 592.5 | C8: 3598 | D8: 592.5 | E8: 3598 | F8: =D8-B8 -> 0 | G8: =E8-C8 -> 0 | I8: 258.88
A9: Till 2 Coffee Right | B9: 249.5 | C9: 1534.22 | D9: =249.5 -> 249.5 | E9: 1534.22 | F9: =D9-B9+B40 -> 0 | G9: =E9-C9 -> 0 | I9: 105.3
A10: Till 3 Sushi | E10: =SUM(E38+F38) -> 0 | F10: =D10-B10 -> 0 | G10: =E10-C10 -> 0
A11: Till 4 Panine | B11: 482 | C11: 2211.6 | D11: 482 | E11: 2211.6 | F11: =D11-B11 -> 0 | G11: =E11-C11 -> 0 | I11: 187.85
A12: Till 5 Salad | E12: =SUM(E40+F40) -> 0 | F12: =D12-B12 -> 0 | G12: =E12-C12 -> 0
A13: Till 6 Pizza | B13: 126.7 | C13: 943.25 | D13: 134 | E13: 943.25 | F13: =D13-B13 -> 7.3 | G13: =E13-C13 -> 0 | I13: 72.4
A14: Till 7 Kebab | B14: 44.7 | C14: 1299.03 | D14: 50.4 | E14: 1299.03 | F14: =D14-B14 -> 5.7 | G14: =E14-C14 -> 0 | I14: 121.55
A15: Till 8 Hot Food | B15: 68.5 | C15: 1289.15 | D15: 76.5 | E15: 1289.15 | F15: =D15-B15 -> 8 | G15: =E15-C15 -> 0 | I15: 114.82
A16: Till 9 Wok | B16: 862.8 | C16: 5892.7 | D16: =874.9 -> 874.9 | E16: 5892.7 | F16: =D16-B16 -> 12.1 | G16: =E16-C16 -> 0 | I16: 555.81
A17: Till 10 Juice Bar | B17: 210.4 | C17: 1299.45 | D17: 210.4 | E17: 1299.45 | F17: =D17-B17 -> 0 | G17: =E17-C17 -> 0 | I17: 28.86
A18: Main Cafe Total | B18: =SUM(B8:B17) -> 2637.1 | C18: =SUM(C8:C17) -> 18067.4 | D18: =SUM(D8:D17) -> 2670.2 | E18: =SUM(E8:E17) -> 18067.4 | F18: =SUM(F8:F17) -> 33.1 | G18: =SUM(G8:G17) -> 0 | H18: =SUM(H8:H17) -> 0 | I18: =SUM(I8:I17) -> 1445.47
A19: Catering on the same day | B19: =SUM(D104) -> 0 | C19: =F104+E104 -> 0 | E19: =SUM(E46+F46-E47-F47) -> 0 | F19: =D19-B19 -> 0 | G19: =E19-C19 -> 0 | H19: =SUM(C118) -> 0 | I19: =(D19+E19+H19)*0.95/11 -> 0
A20: Smart App café
A21: Smart App catering
A22: Westend
A23: TOTAL | B23: =SUM(B3+B4+B5+B6+B7+B18+B19+B22) -> 3465.6 | C23: =SUM(C3+C4+C5+C6+C7+C18+C19+C20+C21+C22) -> 23229.26 | D23: =SUM(D3+D4+D5+D6+D7+D18+D19+D20+D21+D22)-2167.1-611.7-565.3-114-22 -> 17.5 | E23: =SUM(E3+E4+E5+E6+E7+E18+E19+E20+E21+E22) -> 23227.26 | F23: =SUM(F3+F4+F5+F6+F7+F18+F19+F20+F21+F22) -> 32 | G23: =SUM(G3+G4+G5+G6+G7+G18+G19+G20+G21+G22) -> -2 | H23: =SUM(H3+H4+H5+H6+H7+H18+H19+H20+H21+H22) -> 0 | I23: =SUM(I3+I4+I5+I6+I7+I18+I19+I20+I21+I22) -> 1867.99
A24: Cash
A25: INVOICES PAID Cash | B25: Total Inc GST | C25: use till coffee right only | E25: Banking details | G25: Amount deposited
A26: pendle meat 71581 | C26: 2167.1 | E26: Name of Staff | G26: Bank branch
A27: patrick inv 247576 | C27: 611.7 | E27: Reciept | G27: Time | H27: :
A28: patrick inv 248203 | C28: 565.3
A29: westmead pertol | C29: 114.1 | H29: Today Total income | I29: =SUM(B23+C23+G23+F23+H23-I23) -> 24856.87
A30: coles | C30: 22 | D30: Credit Cards Reconcile | E30: Amex | F30: CR+DR | H30: TOTAL $ in SAFE | I30: =SUM(D23+'12th'!I30-'13th'!H25) -> 517.54
A31: SUPPLIER6 | D31: COFFEE THERAPY
A32: SUPPLIER7 | D32: HEALTHY FILLINGS
A33: SUPPLIER8 | D33: OUTPATIENT
A34: SUPPLIER9 | D34: COFFEE BOX
A35: SUPPLIER10 | D35: Green Organic
A36: SUPPLIER11 | D36: Till 1 Coffee Left
A37: SUPPLIER12 | D37: Till 2 Coffee Right
A38: SUPPLIER13 | D38: Till 3 Sushi
A39: SUPPLIER14 | D39: Till 4 Panine
A40: TOTAL Bills Paid Cash | B40: =SUM(B26:B39) -> 0 | D40: Till 5 Salad
...

Sheet 14th
A1: Zouki Westmead | G1: should be $0
A2: =SUM('13th'!A2+1) -> 45883 | B2: Cash Read | C2: CC Read | D2: Cash Collected | E2: Eftpos Collected | F2: +/- over under Cash | G2: +/- over under CC | H2: Acc/smart Cards | I2: GST Read
A3: COFFEE THERAPY | B3: 116.1 | C3: 727.76 | D3: 116.1 | E3: 727.26 | F3: =D3-B3 -> 0 | G3: =E3-C3 -> -0.5 | I3: 64.22
A4: HEALTHY FILLINGS | E4: =SUM(E32+F32) -> 0 | F4: =D4-B4 -> 0 | G4: =E4-C4 -> 0
A5: OUTPATIENT | B5: 126.1 | C5: 2897.77 | D5: 126.1 | E5: 2897.77 | F5: =D5-B5 -> 0 | G5: =E5-C5 -> 0 | I5: 219.28
A6: COFFEE BOX | B6: 274.8 | C6: 1270.73 | D6: 274.8 | E6: 1270.73 | F6: =D6-B6 -> 0 | G6: =E6-C6 -> 0 | I6: 114.27
A7: Green Organic | B7: 96.4 | C7: 1060.76 | D7: 96.4 | E7: 1060.76 | F7: =D7-B7 -> 0 | G7: =E7-C7 -> 0 | I7: 82.95
A8: Till 1 Coffee Left | B8: 618 | C8: 3882.47 | D8: 619.4 | E8: 3882.47 | F8: =D8-B8 -> 1.4 | G8: =E8-C8 -> 0 | I8: 277.62
A9: Till 2 Coffee Right | B9: 338.1 | C9: 2080.29 | D9: 338.1 | E9: 2080.29 | F9: =D9-B9+B40 -> 0 | G9: =E9-C9 -> 0 | I9: 151.71
A10: Till 3 Sushi | E10: =SUM(E38+F38) -> 0 | F10: =D10-B10 -> 0 | G10: =E10-C10 -> 0
A11: Till 4 Panine | B11: 219.7 | C11: 2366.9 | D11: 220.65 | E11: 2366.9 | F11: =D11-B11 -> 0.95 | G11: =E11-C11 -> 0 | I11: 181.4
A12: Till 5 Salad | E12: =SUM(E40+F40) -> 0 | F12: =D12-B12 -> 0 | G12: =E12-C12 -> 0
A13: Till 6 Pizza | B13: 83.3 | C13: 981.57 | D13: 84.3 | E13: 981.57 | F13: =D13-B13 -> 1 | G13: =E13-C13 -> 0 | I13: 74.56
A14: Till 7 Kebab | B14: 290.8 | C14: 1674.77 | D14: 290.8 | E14: 1674.77 | F14: =D14-B14 -> 0 | G14: =E14-C14 -> 0 | I14: 172.31
A15: Till 8 Hot Food | B15: 297.5 | C15: 1597.61 | D15: 297.5 | E15: 1597.61 | F15: =D15-B15 -> 0 | G15: =E15-C15 -> 0 | I15: 155.27
A16: Till 9 Wok | B16: 932.5 | C16: 6433.09 | D16: =933.5 -> 933.5 | E16: 6433.09 | F16: =D16-B16 -> 1 | G16: =E16-C16 -> 0 | I16: 587.05
A17: Till 10 Juice Bar | B17: 231.1 | C17: 1098.39 | D17: 231.1 | E17: 1098.39 | F17: =D17-B17 -> 0 | G17: =E17-C17 -> 0 | I17: 1.15
A18: Main Cafe Total | B18: =SUM(B8:B17) -> 3011 | C18: =SUM(C8:C17) -> 20115.09 | D18: =SUM(D8:D17) -> 3015.35 | E18: =SUM(E8:E17) -> 20115.09 | F18: =SUM(F8:F17) -> 4.35 | G18: =SUM(G8:G17) -> 0 | H18: =SUM(H8:H17) -> 0 | I18: =SUM(I8:I17) -> 1601.07
A19: Catering on the same day | B19: =SUM(D104) -> 0 | C19: =F104+E104 -> 0 | E19: =SUM(E46+F46-E47-F47) -> 0 | F19: =D19-B19 -> 0 | G19: =E19-C19 -> 0 | H19: =SUM(C118) -> 0 | I19: =(D19+E19+H19)*0.95/11 -> 0
A20: Smart App café
A21: Smart App catering
A22: Westend
A23: TOTAL | B23: =SUM(B3+B4+B5+B6+B7+B18+B19+B22) -> 3624.4 | C23: =SUM(C3+C4+C5+C6+C7+C18+C19+C20+C21+C22) -> 26072.11 | D23: =SUM(D3+D4+D5+D6+D7+D18+D19+D20+D21+D22)-3255-323.4 -> 50.35 | E23: =SUM(E3+E4+E5+E6+E7+E18+E19+E20+E21+E22) -> 26071.61 | F23: =SUM(F3+F4+F5+F6+F7+F18+F19+F20+F21+F22) -> 4.35 | G23: =SUM(G3+G4+G5+G6+G7+G18+G19+G20+G21+G22) -> -0.5 | H23: =SUM(H3+H4+H5+H6+H7+H18+H19+H20+H21+H22) -> 0 | I23: =SUM(I3+I4+I5+I6+I7+I18+I19+I20+I21+I22) -> 2081.79
A24: Cash
A25: INVOICES PAID Cash | B25: Total Inc GST | C25: use till coffee right only | E25: Banking details | G25: Amount deposited
A26: patrickinv 247663 | C26: 1525.8 | E26: Name of Staff | G26: Bank branch
A27: patrickinv 247982 | C27: 1729 | E27: Reciept | G27: Time | H27: :
A28: coles | C28: 323.43
A29: SUPPLIER4 | H29: Today Total income | I29: =SUM(B23+C23+G23+F23+H23-I23) -> 27618.57
A30: SUPPLIER5 | D30: Credit Cards Reconcile | E30: Amex | F30: CR+DR | H30: TOTAL $ in SAFE | I30: =SUM(D23+'13th'!I30-'14th'!H25) -> 567.89
A31: SUPPLIER6 | D31: COFFEE THERAPY
A32: SUPPLIER7 | D32: HEALTHY FILLINGS
A33: SUPPLIER8 | D33: OUTPATIENT
A34: SUPPLIER9 | D34: COFFEE BOX
A35: SUPPLIER10 | D35: Green Organic
A36: SUPPLIER11 | D36: Till 1 Coffee Left
A37: SUPPLIER12 | D37: Till 2 Coffee Right
A38: SUPPLIER13 | D38: Till 3 Sushi
A39: SUPPLIER14 | D39: Till 4 Panine
A40: TOTAL Bills Paid Cash | B40: =SUM(B26:B39) -> 0 | D40: Till 5 Salad
...

Sheet 15th
A1: Zouki Westmead | G1: should be $0
A2: =SUM('14th'!A2+1) -> 45884 | B2: Cash Read | C2: CC Read | D2: Cash Collected | E2: Eftpos Collected | F2: +/- over under Cash | G2: +/- over under CC | H2: Acc/smart Cards | I2: GST Read
A3: COFFEE THERAPY | E3: =SUM(E31+F31) -> 0 | F3: =D3-B3 -> 0 | G3: =E3-C3 -> 0
A4: HEALTHY FILLINGS | E4: =SUM(E32+F32) -> 0 | F4: =D4-B4 -> 0 | G4: =E4-C4 -> 0
A5: OUTPATIENT | E5: =SUM(E33+F33) -> 0 | F5: =D5-B5 -> 0 | G5: =E5-C5 -> 0
A6: COFFEE BOX | E6: =SUM(E34+F34) -> 0 | F6: =D6-B6 -> 0 | G6: =E6-C6 -> 0
A7: Green Organic | E7: =SUM(E35+F35) -> 0 | F7: =D7-B7 -> 0 | G7: =E7-C7 -> 0
A8: Till 1 Coffee Left | E8: =SUM(E36+F36) -> 0 | F8: =D8-B8 -> 0 | G8: =E8-C8 -> 0
A9: Till 2 Coffee Right | E9: =SUM(E37+F37) -> 0 | F9: =D9-B9+B40 -> 0 | G9: =E9-C9 -> 0
A10: Till 3 Sushi | E10: =SUM(E38+F38) -> 0 | F10: =D10-B10 -> 0 | G10: =E10-C10 -> 0
A11: Till 4 Panine | E11: =SUM(E39+F39) -> 0 | F11: =D11-B11 -> 0 | G11: =E11-C11 -> 0
A12: Till 5 Salad | E12: =SUM(E40+F40) -> 0 | F12: =D12-B12 -> 0 | G12: =E12-C12 -> 0
A13: Till 6 Pizza | E13: =SUM(E41+F41) -> 0 | F13: =D13-B13 -> 0 | G13: =E13-C13 -> 0
A14: Till 7 Kebab | E14: =SUM(E42+F42) -> 0 | F14: =D14-B14 -> 0 | G14: =E14-C14 -> 0
A15: Till 8 Hot Food | E15: =SUM(E43+F43) -> 0 | F15: =D15-B15 -> 0 | G15: =E15-C15 -> 0
A16: Till 9 Wok | E16: =SUM(E44+F44) -> 0 | F16: =D16-B16 -> 0 | G16: =E16-C16 -> 0
A17: Till 10 Juice Bar | E17: =SUM(E45+F45) -> 0 | F17: =D17-B17 -> 0 | G17: =E17-C17 -> 0
A18: Main Cafe Total | B18: =SUM(B8:B17) -> 0 | C18: =SUM(C8:C17) -> 0 | D18: =SUM(D8:D17) -> 0 | E18: =SUM(E8:E17) -> 0 | F18: =SUM(F8:F17) -> 0 | G18: =SUM(G8:G17) -> 0 | H18: =SUM(H8:H17) -> 0 | I18: =SUM(I8:I17) -> 0
A19: Catering on the same day | B19: =SUM(D104) -> 0 | C19: =F104+E104 -> 0 | E19: =SUM(E46+F46-E47-F47) -> 0 | F19: =D19-B19 -> 0 | G19: =E19-C19 -> 0 | H19: =SUM(C118) -> 0 | I19: =(D19+E19+H19)*0.95/11 -> 0
A20: Smart App café
A21: Smart App catering
A22: Westend
A23: TOTAL | B23: =SUM(B3+B4+B5+B6+B7+B18+B19+B22) -> 0 | C23: =SUM(C3+C4+C5+C6+C7+C18+C19+C20+C21+C22) -> 0 | D23: =SUM(D3+D4+D5+D6+D7+D18+D19+D20+D21+D22) -> 0 | E23: =SUM(E3+E4+E5+E6+E7+E18+E19+E20+E21+E22) -> 0 | F23: =SUM(F3+F4+F5+F6+F7+F18+F19+F20+F21+F22) -> 0 | G23: =SUM(G3+G4+G5+G6+G7+G18+G19+G20+G21+G22) -> 0 | H23: =SUM(H3+H4+H5+H6+H7+H18+H19+H20+H21+H22) -> 0 | I23: =SUM(I3+I4+I5+I6+I7+I18+I19+I20+I21+I22) -> 0
A24: Cash
A25: INVOICES PAID Cash | B25: Total Inc GST | C25: use till coffee right only | E25: Banking details | G25: Amount deposited
A26: SUPPLIER1 | E26: Name of Staff | G26: Bank branch
A27: SUPPLIER2 | E27: Reciept | G27: Time | H27: :
A28: SUPPLIER3
A29: SUPPLIER4 | H29: Today Total income | I29: =SUM(B23+C23+G23+F23+H23-I23) -> 0
A30: SUPPLIER5 | D30: Credit Cards Reconcile | E30: Amex | F30: CR+DR | H30: TOTAL $ in SAFE | I30: =SUM(D23+'14th'!I30-'15th'!H25) -> 567.89
A31: SUPPLIER6 | D31: COFFEE THERAPY
A32: SUPPLIER7 | D32: HEALTHY FILLINGS
A33: SUPPLIER8 | D33: OUTPATIENT
A34: SUPPLIER9 | D34: COFFEE BOX
A35: SUPPLIER10 | D35: Green Organic
A36: SUPPLIER11 | D36: Till 1 Coffee Left
A37: SUPPLIER12 | D37: Till 2 Coffee Right
A38: SUPPLIER13 | D38: Till 3 Sushi
A39: SUPPLIER14 | D39: Till 4 Panine
A40: TOTAL Bills Paid Cash | B40: =SUM(B26:B39) -> 0 | D40: Till 5 Salad
...

Sheet 16th
A1: Zouki Westmead | G1: should be $0
A2: =SUM('15th'!A2+1) -> 45885 | B2: Cash Read | C2: CC Read | D2: Cash Collected | E2: Eftpos Collected | F2: +/- over under Cash | G2: +/- over under CC | H2: Acc/smart Cards | I2: GST Read
A3: COFFEE THERAPY | E3: =SUM(E31+F31) -> 0 | F3: =D3-B3 -> 0 | G3: =E3-C3 -> 0
A4: HEALTHY FILLINGS | E4: =SUM(E32+F32) -> 0 | F4: =D4-B4 -> 0 | G4: =E4-C4 -> 0
A5: OUTPATIENT | E5: =SUM(E33+F33) -> 0 | F5: =D5-B5 -> 0 | G5: =E5-C5 -> 0
A6: COFFEE BOX | E6: =SUM(E34+F34) -> 0 | F6: =D6-B6 -> 0 | G6: =E6-C6 -> 0
A7: Green Organic | E7: =SUM(E35+F35) -> 0 | F7: =D7-B7 -> 0 | G7: =E7-C7 -> 0
A8: Till 1 Coffee Left | E8: =SUM(E36+F36) -> 0 | F8: =D8-B8 -> 0 | G8: =E8-C8 -> 0
A9: Till 2 Coffee Right | E9: =SUM(E37+F37) -> 0 | F9: =D9-B9+B40 -> 0 | G9: =E9-C9 -> 0
A10: Till 3 Sushi | E10: =SUM(E38+F38) -> 0 | F10: =D10-B10 -> 0 | G10: =E10-C10 -> 0
A11: Till 4 Panine | E11: =SUM(E39+F39) -> 0 | F11: =D11-B11 -> 0 | G11: =E11-C11 -> 0
A12: Till 5 Salad | E12: =SUM(E40+F40) -> 0 | F12: =D12-B12 -> 0 | G12: =E12-C12 -> 0
A13: Till 6 Pizza | E13: =SUM(E41+F41) -> 0 | F13: =D13-B13 -> 0 | G13: =E13-C13 -> 0
A14: Till 7 Kebab | E14: =SUM(E42+F42) -> 0 | F14: =D14-B14 -> 0 | G14: =E14-C14 -> 0
A15: Till 8 Hot Food | E15: =SUM(E43+F43) -> 0 | F15: =D15-B15 -> 0 | G15: =E15-C15 -> 0
A16: Till 9 Wok | E16: =SUM(E44+F44) -> 0 | F16: =D16-B16 -> 0 | G16: =E16-C16 -> 0
A17: Till 10 Juice Bar | E17: =SUM(E45+F45) -> 0 | F17: =D17-B17 -> 0 | G17: =E17-C17 -> 0
A18: Main Cafe Total | B18: =SUM(B8:B17) -> 0 | C18: =SUM(C8:C17) -> 0 | D18: =SUM(D8:D17) -> 0 | E18: =SUM(E8:E17) -> 0 | F18: =SUM(F8:F17) -> 0 | G18: =SUM(G8:G17) -> 0 | H18: =SUM(H8:H17) -> 0 | I18: =SUM(I8:I17) -> 0
A19: Catering on the same day | B19: =SUM(D104) -> 0 | C19: =F104+E104 -> 0 | E19: =SUM(E46+F46-E47-F47) -> 0 | F19: =D19-B19 -> 0 | G19: =E19-C19 -> 0 | H19: =SUM(C118) -> 0 | I19: =(D19+E19+H19)*0.95/11 -> 0
A20: Smart App café
A21: Smart App catering
A22: Westend
A23: TOTAL | B23: =SUM(B3+B4+B5+B6+B7+B18+B19+B22) -> 0 | C23: =SUM(C3+C4+C5+C6+C7+C18+C19+C20+C21+C22) -> 0 | D23: =SUM(D3+D4+D5+D6+D7+D18+D19+D20+D21+D22) -> 0 | E23: =SUM(E3+E4+E5+E6+E7+E18+E19+E20+E21+E22) -> 0 | F23: =SUM(F3+F4+F5+F6+F7+F18+F19+F20+F21+F22) -> 0 | G23: =SUM(G3+G4+G5+G6+G7+G18+G19+G20+G21+G22) -> 0 | H23: =SUM(H3+H4+H5+H6+H7+H18+H19+H20+H21+H22) -> 0 | I23: =SUM(I3+I4+I5+I6+I7+I18+I19+I20+I21+I22) -> 0
A24: Cash
A25: INVOICES PAID Cash | B25: Total Inc GST | C25: use till coffee right only | E25: Banking details | G25: Amount deposited
A26: SUPPLIER1 | E26: Name of Staff | G26: Bank branch
A27: SUPPLIER2 | E27: Reciept | G27: Time | H27: :
A28: SUPPLIER3
